Workbook

Sheet P&L Summary
B2: Unlimited Avenues
B3: Profit & Loss Statement
B4: January – March 2026 (YTD)
C6: Jan-26 | D6: Feb-26 | E6: Mar-26 | F6: Q1 Total
B7: ($ in whole dollars)
B9: REVENUE
B10: Gross Sales | C10: 2850138.7 | D10: 2996715.6 | E10: 3590404 | F10: =SUM(C10:E10) -> 9437258.3
B11: Chargebacks | C11: -3004.64 | D11: -5735.18 | E11: -3750.42 | F11: =SUM(C11:E11) -> -12490.24
B12: Net Revenue | C12: =C10+C11 -> 2847134.1 | D12: =D10+D11 -> 2990980.5 | E12: =E10+E11 -> 3586653.5 | F12: =F10+F11 -> 9424768.1
B14: COST OF GOODS SOLD
B15: Purchases – Import | C15: 3697794.4 | D15: 4209512.6 | E15: 3105996.8 | F15: =SUM(C15:E15) -> 11013304
B16: Purchase Discount | C16: -2197.49 | D16: 14275.52 | E16: -1100.1 | F16: =SUM(C16:E16) -> 10977.93
B17: Sample / Design / Development | C17: 40942.48 | D17: 11302.85 | E17: 33832.47 | F17: =SUM(C17:E17) -> 86077.8
B18: Custom Duty | C18: 0 | D18: 2658.83 | E18: 7621.49 | F18: =SUM(C18:E18) -> 10280.32
B19: Freight In | C19: 0 | D19: 160 | E19: 0 | F19: =SUM(C19:E19) -> 160
B20: Ocean Freight & Handling | C20: 37619 | D20: 5817.52 | E20: 4681 | F20: =SUM(C20:E20) -> 48117.52
B21: Warehouse Expenses | C21: 43768.88 | D21: 43162.82 | E21: 7436.7 | F21: =SUM(C21:E21) -> 94368.4
B22: Total COGS | C22: =SUM(C15:C21) -> 3817927.3 | D22: =SUM(D15:D21) -> 4286890.2 | E22: =SUM(E15:E21) -> 3158468.3 | F22: =SUM(F15:F21) -> 11263286
B24: GROSS PROFIT | C24: =C12-C22 -> -970793.23 | D24: =D12-D22 -> -1295909.7 | E24: =E12-E22 -> 428185.19 | F24: =F12-F22 -> -1838517.7
B25: Gross Margin % | C25: =IF(C12=0,0,C24/C12) -> -0.34097208 | D25: =IF(D12=0,0,D24/D12) -> -0.43327253 | E25: =IF(E12=0,0,E24/E12) -> 0.11938293 | F25: =IF(F12=0,0,F24/F12) -> -0.19507299
B27: OPERATING EXPENSES
B28: Sales Commissions | C28: 4120.35 | D28: 0 | E28: 0 | F28: =SUM(C28:E28) -> 4120.35
B29: Donations | C29: 151 | D29: 151 | E29: 151 | F29: =SUM(C29:E29) -> 453
B30: Factor Commission & Fees | C30: 6931.22 | D30: 8915.1 | E30: 0 | F30: =SUM(C30:E30) -> 15846.32
B31: Factor Interest | C31: 6474.03 | D31: 17569.1 | E31: 0 | F31: =SUM(C31:E31) -> 24043.13
B32: Finance Charges | C32: 11005.9 | D32: 6673.24 | E32: 2615.3 | F32: =SUM(C32:E32) -> 20294.44
B33: Health Insurance | C33: 5991.91 | D33: 4363.6 | E33: 2181.8 | F33: =SUM(C33:E33) -> 12537.31
B34: Inspection of Goods | C34: 0 | D34: 22498.21 | E34: 0 | F34: =SUM(C34:E34) -> 22498.21
B35: Factor Misc Charges | C35: 350 | D35: 475 | E35: 0 | F35: =SUM(C35:E35) -> 825
B36: Modelling Services | C36: 0 | D36: 330 | E36: 330 | F36: =SUM(C36:E36) -> 660
B37: Sales Promotion | C37: 223 | D37: 0 | E37: 0 | F37: =SUM(C37:E37) -> 223
B38: Showroom Expenses | C38: 151.25 | D38: 374.36 | E38: 211.25 | F38: =SUM(C38:E38) -> 736.86
B39: Statement Charges | C39: 95 | D39: 95 | E39: 95 | F39: =SUM(C39:E39) -> 285
... B50: Rent Expense | C50: 0 | D50: 9515 | E50: 0 | F50: =SUM(C50:E50) -> 9515
B51: Total Operating Expenses | C51: =SUM(C28:C50) -> 43854.26 | D51: =SUM(D28:D50) -> 102675.46 | E51: =SUM(E28:E50) -> 14639.24 | F51: =SUM(F28:F50) -> 161168.96
B52: OpEx % of Revenue | C52: =IF(C12=0,0,C51/C12) -> 0.015402949 | D52: =IF(D12=0,0,D51/D12) -> 0.034328362 | E52: =IF(E12=0,0,E51/E12) -> 0.0040815874 | F52: =IF(F12=0,0,F51/F12) -> 0.017100576
B54: NET OPERATING INCOME | C54: =C24-C51 -> -1014647.5 | D54: =D24-D51 -> -1398585.1 | E54: =E24-E51 -> 413545.95 | F54: =F24-F51 -> -1999686.7
B55: Operating Margin % | C55: =IF(C12=0,0,C54/C12) -> -0.35637503 | D55: =IF(D12=0,0,D54/D12) -> -0.4676009 | E55: =IF(E12=0,0,E54/E12) -> 0.11530134 | F55: =IF(F12=0,0,F54/F12) -> -0.21217357
B57: OTHER INCOME / (EXPENSE)
B58: Refund on Credit Card | C58: 0 | D58: 558 | E58: 0 | F58: =SUM(C58:E58) -> 558
...

Sheet COGS Analysis
B2: COGS Breakdown & Analysis
B3: Q1 2026
C5: Jan-26 | D5: Feb-26 | E5: Mar-26 | F5: Q1 Total
B7: Purchases – Import | C7: 3697794.4 | D7: 4209512.6 | E7: 3105996.8 | F7: =SUM(C7:E7) -> 11013304
B8: Purchase Discount | C8: -2197.49 | D8: 14275.52 | E8: -1100.1 | F8: =SUM(C8:E8) -> 10977.93
B9: Sample / Design / Dev | C9: 40942.48 | D9: 11302.85 | E9: 33832.47 | F9: =SUM(C9:E9) -> 86077.8
B10: Custom Duty | C10: 0 | D10: 2658.83 | E10: 7621.49 | F10: =SUM(C10:E10) -> 10280.32
B11: Freight In | C11: 0 | D11: 160 | E11: 0 | F11: =SUM(C11:E11) -> 160
B12: Ocean Freight & Handling | C12: 37619 | D12: 5817.52 | E12: 4681 | F12: =SUM(C12:E12) -> 48117.52
B13: Warehouse Expenses | C13: 43768.88 | D13: 43162.82 | E13: 7436.7 | F13: =SUM(C13:E13) -> 94368.4
B14: Total COGS | C14: =SUM(C7:C13) -> 3817927.3 | D14: =SUM(D7:D13) -> 4286890.2 | E14: =SUM(E7:E13) -> 3158468.3 | F14: =SUM(F7:F13) -> 11263286
B16: COGS % of Revenue | C16: =IF('P&L Summary'!C12=0,0,C14/'P&L Summary'!C12) -> 1.3409721 | D16: =IF('P&L Summary'!D12=0,0,D14/'P&L Summary'!D12) -> 1.4332725 | E16: =IF('P&L Summary'!E12=0,0,E14/'P&L Summary'!E12) -> 0.88061707 | F16: =IF('P&L Summary'!F12=0,0,F14/'P&L Summary'!F12) -> 1.195073

Sheet Key Metrics
B2: Key Financial Metrics
B3: Q1 2026 Summary
B5: Metric | C5: Jan-26 | D5: Feb-26 | E5: Mar-26 | F5: Q1 Total
B7: Net Revenue | C7: ='P&L Summary'!C12 -> 2847134.1 | D7: ='P&L Summary'!D12 -> 2990980.5 | E7: ='P&L Summary'!E12 -> 3586653.5 | F7: ='P&L Summary'!F12 -> 9424768.1
B8: Total COGS | C8: ='P&L Summary'!C22 -> 3817927.3 | D8: ='P&L Summary'!D22 -> 4286890.2 | E8: ='P&L Summary'!E22 -> 3158468.3 | F8: ='P&L Summary'!F22 -> 11263286
B9: Gross Profit | C9: ='P&L Summary'!C24 -> -970793.23 | D9: ='P&L Summary'!D24 -> -1295909.7 | E9: ='P&L Summary'!E24 -> 428185.19 | F9: ='P&L Summary'!F24 -> -1838517.7
B10: Gross Margin % | C10: ='P&L Summary'!C25 -> -0.34097208 | D10: ='P&L Summary'!D25 -> -0.43327253 | E10: ='P&L Summary'!E25 -> 0.11938293 | F10: ='P&L Summary'!F25 -> -0.19507299
B12: Total OpEx | C12: ='P&L Summary'!C51 -> 43854.26 | D12: ='P&L Summary'!D51 -> 102675.46 | E12: ='P&L Summary'!E51 -> 14639.24 | F12: ='P&L Summary'!F51 -> 161168.96
B13: OpEx % of Revenue | C13: ='P&L Summary'!C52 -> 0.015402949 | D13: ='P&L Summary'!D52 -> 0.034328362 | E13: ='P&L Summary'!E52 -> 0.0040815874 | F13: ='P&L Summary'!F52 -> 0.017100576
B15: Net Operating Income | C15: ='P&L Summary'!C54 -> -1014647.5 | D15: ='P&L Summary'!D54 -> -1398585.1 | E15: ='P&L Summary'!E54 -> 413545.95 | F15: ='P&L Summary'!F54 -> -1999686.7
B16: Operating Margin % | C16: ='P&L Summary'!C55 -> -0.35637503 | D16: ='P&L Summary'!D55 -> -0.4676009 | E16: ='P&L Summary'!E55 -> 0.11530134 | F16: ='P&L Summary'!F55 -> -0.21217357
B18: Net Income | C18: ='P&L Summary'!C61 -> -1014647.5 | D18: ='P&L Summary'!D61 -> -1398027.1 | E18: ='P&L Summary'!E61 -> 413545.95 | F18: ='P&L Summary'!F61 -> -1999128.7
B19: Net Margin % | C19: ='P&L Summary'!C62 -> -0.35637503 | D19: ='P&L Summary'!D62 -> -0.46741434 | E19: ='P&L Summary'!E62 -> 0.11530134 | F19: ='P&L Summary'!F62 -> -0.21211436
